catch(...) {
  cout << "an exception was thrown" << endl;
}
