catch(...) {
  cout << "an exception was thrown" << endl;
  // Освобождение ресурсов
  throw;
}
